Workbook
Name Запрос: ОКВЭД2!$A$2:$B$2795

Sheet Ввод данных
B2: Форма ввода данных проекта
A3: =IF(D4=Списки!A3,"Блок 1 - Титульный лист проекта СР","Блок 1") -> Блок 1 - Титульный лист проекта СР | C3: Общая информация Заполнить белые ячейки, выбрать подходящие варианты из выпадающего списка
C4: Вид поддержки: | D4: РЦК
C5: Название предприятия:
C6: Регион:
C7: Отрасль:
C8: ОКВЭД потока | D8: Код: | F8: =VLOOKUP(E8,ОКВЭД2!A4:B2795,2) -> #N/A
C9: Название проекта:
D10: ↑Название проекта должно соответствовать структуре: "Оптимизация производства изделия", "Оптимизация процесса продаж продукта", "Оптимизация предоставления услуги …" и т.д.
C11: Срок реализации: | D11: 6 месяцев
B12: =IF(D4=Списки!A3,"Блок 2 - п. 1.1, п 2.1 и 2.4","Блок 2") -> Блок 2 - п. 1.1, п 2.1 и 2.4 | C12: Обоснование выбора потока Заполнить белые ячейки, выбрать подходящие варианты из выпадающего списка
C13: Причина выбора потока:
C14: Доля в выручке, %
C15: Причина выбора потока
C16: Проблемы на потоке до вступления в проект:
C17: № | D17: Описание проблемы
C18: 1
C19: =IF(D18="","",2)
C20: =IF(D19="","",3)
B21: =IF(D4=Списки!A3,"Блок 3 - Карточка протокола, п. 1.6, 2.1 и 2.3","Блок 3") -> Блок 3 - Карточка протокола, п. 1.6, 2.1 и 2.3 | C21: Ключевые показатели проекта Заполнить белые ячейки, выбрать правильные единицы измерения
C22: Экономический эффект | D22: Годовой эффект | E22: Единица измерения | F22: Описание
C23: Дополнительная выручка | E23: млн руб. | F23: Ввести значение ячейки G14 из листа "Экономический эффект" модели расчета экономического эффекта
C24: Дополнительная прибыль | E24: млн руб. | F24: Ввести значение ячейки G12 из листа "Экономический эффект" модели расчета экономического эффекта. В случае заполнения расчета вспомогательного процесса ввести значение реального экономического эффекта.
D25: ↑Годовой экономический эффект должен соответствовать модели расчета. Выполнить математическое округление до целого значения для корректного отображения на листе "Вскрытие резервов".
C26: Обязательные показатели для заполнения | D26: Наименование продукта пилотного проекта в родительном падеже | E26: До | F26: После | G26: Единица измерения | H26: Поставить галочку, если необходимо в ВР отобразить относительное изменение показателя в % | J26: Расчет для ВР
C27: Выработка | H27: =(F27-E27)/E27 -> #DIV/0! | I27: =CONCATENATE("+",IF((F27-E27)<1,ROUND((F27-E27),2),ROUND((F27-E27),0))) -> +0 | J27: =CONCATENATE("+",ROUND(H27*100,0),"%") -> #DIV/0!
C28: Время протекания процесса | H28: FALSE | I28: =(F28-E28)/E28 -> #DIV/0! | J28: =IF(H28,CONCATENATE("",ROUND(I28*100,0)),CONCATENATE("-",ROUND(E28-F28,0))) -> -0
C29: Численность потока | G29: чел. | H29: =E29-F29 -> 0
C30: Закрыта кадровая потребность | F30: =ROUNDUP((E29*H27)+(E29-F29),0) -> #DIV/0! | H30: ← Выбери правильную форму единицы измерения в зависимости от рассчитанного значения закрытой кадровой потребности
C31: Индивидуальный показатель проекта (заполняется при наличии) | D31: Поставить галочку, если показатель по результатам проекта вырос | E31: Определение абсолютного изменения показателя | H31: Поставить галочку, если необходимо в ВР отобразить относительное изменение показателя в % | I31: Изменение в % | J31: Расчет для ВР
E32: До | F32: После | G32: Единица измерения
D33: FALSE | H33: FALSE | I33: =IF(D33,(ABS(F33-E33))/E33,(ABS(E33-F33))/E33) -> #DIV/0! | J33: =IF(E33>0,IF(H33,IF(D33,CONCATENATE("+",ROUND(I33*100,0)),CONCATENATE("-",ROUND(I33*100,0))),IF(D33,CONCATENATE("+",ROUND(ABS(F33-E33),0)),CONCATENATE("-",ROUND(ABS(E33-F33),0)))),"")
D34: FALSE | H34: FALSE | I34: =IF(D34,(ABS(F34-E34))/E34,(ABS(E34-F34))/E34) -> #DIV/0! | J34: =IF(E34>0,IF(H34,IF(D34,CONCATENATE("+",ROUND(I34*100,0)),CONCATENATE("-",ROUND(I34*100,0))),IF(D34,CONCATENATE("+",ROUND(ABS(F34-E34),0)),CONCATENATE("-",ROUND(ABS(E34-F34),0)))),"")
C35: ↑При заполнении второй индивидуальный показатель заменит собой на листе "Вскрытие резервов" показатель "Время протекания процесса".
C36: Абсолютное изменение - это простая разница между новым и старым значением, относительное изменение - это отношение абсолютного изменения к базовому (начальному) значению. Как выбрать правильное изменение? Пример 1: Большой процент — маленькие деньги У вас было 100 рублей, вы нашли на улице еще 100 рублей. Абсолютное изменение: +100 руб. (небольшая сумма). Относительное изменение: +100% (вы увеличили свой капитал в два раза!). Отдаем предпочтение относительному изменению, так как оно выглядит впечатляющим. Пример 2: Маленький процент — огромные деньги У инвестора было 10 000 000 рублей на счету, за год он заработал 500 000 рублей. Абсолютное изменение: +500 000 руб. (огромная сумма). Относительное изменение: +5% (скромная доходность). Выбираем абсолютное изменение, так как оно выглядит солидно.
C38: Объяснение роста выработки Текст формируется автоматически
C39: =Списки!D154 -> #DIV/0!
B40: =IF(D4=Списки!A3,"Блок 4 - п. 2.6 и 3.7.2","Блок 4") -> Блок 4 - п. 2.6 и 3.7.2 | C40: Что сделано в рамках проекта:
C41: При описании мероприятий ниже важно показать физику результата (как именно эти действия конвертировались в главные цифры). Для руководителя предприятия или ФЦК язык «минут и часов» вторичен, первичен язык «мощностей и денег». Важно описать причинно-следственную связь. Выработка на производстве на одного сотрудника растет только когда: 1. сокращаем время цикла (делаем каждую деталь быстрее), 2. устраняем простои (увеличиваем фонд полезного времени), 3. сокращаем численность в потоке Плохо: Перечислены разрозненные факты (подвинули станки, купили инструмент, сделали каталог). Хорошо: Устранение потерь -> Высвобождение часов -> Рост выработки в штуках. Структура формулировок: Устранили простои (ожидание и поиск): сделали раз, сделали два. Высвобождено [Х1] часов → прирост [Y1] шт. Сократили цикл сборки (технология и унификация): сделали раз, сделали два. Высвобождено [Х2] часов → прирост [Y2] шт. Исключили лишние перемещения: сделали раз, сделали два. Высвобождено [Х3] часов → прирост [Y3] шт. Внимание! Необходимо соблюсти математическую прослеживаемость. В первую очередь описать мероприятия с влиянием на выработку. Пример: Выработка выросла на 5 шт/мес. Достигнут рост тремя мероприятиями. Описываем первое с влиянием 3 шт/мес, второе с 1,5 шт/мес и третье с 0,5 шт/мес. В сумме отображен рост показателя. Заполнение 5 полей мероприятий обязательно (43 , 44 , 45, 46, 47 строки). В случае, если заполнен первый (верхний) индивидуальный показатель - описать мероприятия, связанные с ним только в строке 47. В случае заполнения второго (нижниего) индивидуального показателя - описать мероприятия, связанные с ним только в строке 46. Мероприятия в строках 43-45 должны относиться к росту выработки.
C42: Цель оптимизации: выбрать из выпадающего списка подходящие | D42: Направление оптимизации: | G42: Описание мероприятий: ввести в ячейке до 256 символов (2-3 предложения) - ограничение в ячейке. Внимание! Описанные мероприятия должны быть логически связаны с выбранными проблемами в Блоке 2 и с достигнутыми результатами (в частности с показателем Выработки) в Блоке 3
...

Sheet Своя ед.изм
B2: При необходимости, допускается внести единицу измерения которая согласована с руководством и учтена в карточке "О проекта в цифрах" П5 и Протоколе выполнения мероприятий
B3: Правила сокращений: километр – км метр – м минута – мин час - ч штук (штуки) – шт. | E3: Структура: единица продукции/чел./период м²/чел./см шт./чел./сут т/чел./нед

Sheet Фото
A1: Требования к фотографии • Рекомендуется подгрузить в лист "Доп Фото" до 3 фото продукта в разных стадиях (проектирование, производство, ГП), но минимум 1 фото обязательно • На фото должно отсутствовать «брендирование», по которому явно можно понять, о каком предприятии идет речь • Возможно фото финального продукта и/или производственного процесса • На фото может присутствовать персонал (без крупных планов, чтобы нельзя было точно определить, кто присутствует на фото, и без брендов на одежде) • Фото должно быть хорошего качества (не менее 300 dpi) • Фото должно быть понятным и относящимся к производимому продукту/услуге • В случае невозможности сделать фото - грузим изображения продукта из портфолио/сайта предприятия. В случае его отсутствия - найти обезличенное изображение аналогичного продукта в сети интернет
J21: Продукт на производстве
A42: Принципиальный вид продукта | J42: Продукт у клиента

Sheet ВР1
K1: Перед переносом информации в презентацию необходимо выровнять текстовые блоки в разделе "Что сделано в рамках проекта" для равномерного распределения расстояний между ними Для этого: 1. Границы блоков (размер фигуры по высоте) раздела "Что сделано в рамках проекта" должны быть плотно подогнаны к тексту (без лишних пустых полей внутри блока), чтобы обеспечить точное позиционирование. 2. Выделите 5 блоков с текстом, нажимая на них левой кнопкой мыши с одновременно зажатой клавишей SHIFT 3. В верхнем меню Excel выберите "Разметка страницы" 4. Нажмите кнопку "Выровнять" в открывшемся меню 5. В выпадающем меню выберите "Распределить по вертикали" * Либо после выполнения шага 2 зажмите клавишу ALT и нажимайте по очереди клавиши кириллицы З Н В К Для копирования этого листа в презентацию необходимо: 1. Выделить любой объект на листе 2. Нажать CTRL+A - выделить все объекты 3. Нажать CTRL+C - скопировать в буфер * Если так не работает, то включить режим "Выбор объектов" (Главная - Найти и выделить - Выбор объектов). В таком режиме курсор превратится в стрелку и можно выделять целые области, захватывая все фигуры Скопировать (CTRL+C) Вернуться из режима "Выбор объектов" в обычный режим можно нажав клавишу ESC или двойным кликом на листе 4. Вставить скопированные объекты (CTRL+V) на лист презентации 5. Сгруппировать (CTRL+G) и переместить на слайде в необходимое место 6. Необходимую фотографию взять с листа "Фото"

Sheet ВР2
G1: Перед переносом информации в презентацию необходимо выровнять текстовые блоки в разделе "Что сделано в рамках проекта" для равномерного распределения расстояний между ними Для этого: 1. Границы блоков (размер фигуры по высоте) раздела "Что сделано в рамках проекта" должны быть плотно подогнаны к тексту (без лишних пустых полей внутри блока), чтобы обеспечить точное позиционирование. 2. Выделите 5 блоков с текстом, нажимая на них левой кнопкой мыши с одновременно зажатой клавишей SHIFT 3. В верхнем меню Excel выберите "Разметка страницы" 4. Нажмите кнопку "Выровнять" в открывшемся меню 5. В выпадающем меню выберите "Распределить по вертикали" * Либо после выполнения шага 2 зажмите клавишу ALT и нажимайте по очереди клавиши кириллицы З Н В К Для копирования этого листа в презентацию необходимо: 1. Выделить любой объект на листе 2. Нажать CTRL+A - выделить все объекты 3. Нажать CTRL+C - скопировать в буфер * Если так не работает, то включить режим "Выбор объектов" (Главная - Найти и выделить - Выбор объектов). В таком режиме курсор превратится в стрелку и можно выделять целые области, захватывая все фигуры Скопировать (CTRL+C) Вернуться из режима "Выбор объектов" в обычный режим можно нажав клавишу ESC или двойным кликом на листе 4. Вставить скопированные объекты (CTRL+V) на лист презентации 5. Сгруппировать (CTRL+G) и переместить на слайде в необходимое место 6. Необходимую фотографию взять с листа "Фото"

Sheet ВР3
I1: Перед переносом информации в презентацию необходимо выровнять текстовые блоки в разделе "Что сделано в рамках проекта" для равномерного распределения расстояний между ними Для этого: 1. Границы блоков (размер фигуры по высоте) раздела "Что сделано в рамках проекта" должны быть плотно подогнаны к тексту (без лишних пустых полей внутри блока), чтобы обеспечить точное позиционирование. 2. Выделите 5 блоков с текстом, нажимая на них левой кнопкой мыши с одновременно зажатой клавишей SHIFT 3. В верхнем меню Excel выберите "Разметка страницы" 4. Нажмите кнопку "Выровнять" в открывшемся меню 5. В выпадающем меню выберите "Распределить по вертикали" * Либо после выполнения шага 2 зажмите клавишу ALT и нажимайте по очереди клавиши кириллицы З Н В К Для копирования этого листа в презентацию необходимо: 1. Выделить любой объект на листе 2. Нажать CTRL+A - выделить все объекты 3. Нажать CTRL+C - скопировать в буфер * Если так не работает, то включить режим "Выбор объектов" (Главная - Найти и выделить - Выбор объектов). В таком режиме курсор превратится в стрелку и можно выделять целые области, захватывая все фигуры Скопировать (CTRL+C) Вернуться из режима "Выбор объектов" в обычный режим можно нажав клавишу ESC или двойным кликом на листе 4. Вставить скопированные объекты (CTRL+V) на лист презентации 5. Сгруппировать (CTRL+G) и переместить на слайде в необходимое место 6. Необходимую фотографию взять с листа "Фото"

Sheet ВР4
J1: Перед переносом информации в презентацию необходимо выровнять текстовые блоки в разделе "Что сделано в рамках проекта" для равномерного распределения расстояний между ними Для этого: 1. Границы блоков (размер фигуры по высоте) раздела "Что сделано в рамках проекта" должны быть плотно подогнаны к тексту (без лишних пустых полей внутри блока), чтобы обеспечить точное позиционирование. 2. Выделите 5 блоков с текстом, нажимая на них левой кнопкой мыши с одновременно зажатой клавишей SHIFT 3. В верхнем меню Excel выберите "Разметка страницы" 4. Нажмите кнопку "Выровнять" в открывшемся меню 5. В выпадающем меню выберите "Распределить по вертикали" * Либо после выполнения шага 2 зажмите клавишу ALT и нажимайте по очереди клавиши кириллицы З Н В К Для копирования этого листа в презентацию необходимо: 1. Выделить любой объект на листе 2. Нажать CTRL+A - выделить все объекты 3. Нажать CTRL+C - скопировать в буфер * Если так не работает, то включить режим "Выбор объектов" (Главная - Найти и выделить - Выбор объектов). В таком режиме курсор превратится в стрелку и можно выделять целые области, захватывая все фигуры Скопировать (CTRL+C) Вернуться из режима "Выбор объектов" в обычный режим можно нажав клавишу ESC или двойным кликом на листе 4. Вставить скопированные объекты (CTRL+V) на лист презентации 5. Сгруппировать (CTRL+G) и переместить на слайде в необходимое место 6. Необходимую фотографию взять с листа "Фото"

Sheet ВР5
I1: Перед переносом информации в презентацию необходимо выровнять текстовые блоки в разделе "Что сделано в рамках проекта" для равномерного распределения расстояний между ними Для этого: 1. Границы блоков (размер фигуры по высоте) раздела "Что сделано в рамках проекта" должны быть плотно подогнаны к тексту (без лишних пустых полей внутри блока), чтобы обеспечить точное позиционирование. 2. Выделите 5 блоков с текстом, нажимая на них левой кнопкой мыши с одновременно зажатой клавишей SHIFT 3. В верхнем меню Excel выберите "Разметка страницы" 4. Нажмите кнопку "Выровнять" в открывшемся меню 5. В выпадающем меню выберите "Распределить по вертикали" * Либо после выполнения шага 2 зажмите клавишу ALT и нажимайте по очереди клавиши кириллицы З Н В К Для копирования этого листа в презентацию необходимо: 1. Выделить любой объект на листе 2. Нажать CTRL+A - выделить все объекты 3. Нажать CTRL+C - скопировать в буфер * Если так не работает, то включить режим "Выбор объектов" (Главная - Найти и выделить - Выбор объектов). В таком режиме курсор превратится в стрелку и можно выделять целые области, захватывая все фигуры Скопировать (CTRL+C) Вернуться из режима "Выбор объектов" в обычный режим можно нажав клавишу ESC или двойным кликом на листе 4. Вставить скопированные объекты (CTRL+V) на лист презентации 5. Сгруппировать (CTRL+G) и переместить на слайде в необходимое место

Sheet Форматы ВР
B2: ВР1 | C2: ВР2 | D2: ВР3 | E2: ВР4 | F2: ВР5
B3: Для презентации в бело-красном стиле, широкоформатная с шириной 33,867 см и высотой 19,05 см | C3: Для презентации в бело-красном стиле, широкоформатная с шириной 33,867 см и высотой 19,05 см, вполовину слайда | D3: Для классической презентации в бело-синем стиле, формата Экран (16:9) с шириной 25,4 см и высотой 14,288 см | E3: Для классической презентации в бело-синем стиле, формата листа А4 с шириной 27,517 см и высотой 19,05 см | F3: Формат зимы 2025 года в бело-синем стиле, формата Экран (16:9) с шириной 25,4 см и высотой 14,288 см

Sheet Дайджест
A1: Лист формирования отчета по проекту для Дайджеста

Sheet Списки
A1: ВП | B1: Отрасль | C1: Регион | D1: Основные проблемы | E1: Ед. изм для выработки | F1: Ед. изм | G1: Направления мероприятий | H1: Проблемы
A2: ФЦК | B2: Машиностроение | C2: Алтайский край | D2: невыполнение заказов в срок и срыв договорных обязательств | E2: м²/чел./ч | F2: мин | G2: Максимизация времени работы (мероприятия по устранению потерь времени, когда поток стоит или ожидает) | H2: Сокращение простоев оборудования; Сокращение простоев людей; Сокращение ожидания обеспечения материалами; заготовками и инструментом; Сокращение ожидания комплектации заказа; Сокращение ожидания транспортировки.
A3: РЦК | B3: Металлургия | C3: Амурская область | D3: длительное время производства и отгрузки готовой продукции | E3: м²/чел./см | F3: ч | G3: Максимизация темпа процесса (мероприятия повышения скорости потока) | H3: Сокращение циклов операций; Расшивка узких мест; Выравнивание и стандартизация потока; Выстраивание потока единичных изделий.
B4: Нефтегазовая отрасль | C4: Архангельская область | D4: неритмичность производства и невыполнение сменных планов | E4: м²/чел./сут | F4: дн | G4: Минимизация потерь на брак (мероприятия по сокращению издержек на доработку несоответствующей продукции и окончательный брак) | H4: Сокращение входного, внутреннего брака; Сокращение производственного брака; Сокращение доработки/доводки продукции; Сокращение рекламаций.
B5: Химическая промышленность | C5: Астраханская область | D5: снижение объема продаж, выручки и маржинальной прибыли | E5: м²/чел./нед | G5: Оптимизация трудозатрат (мероприятия по сокращению трудоемкости ручных операций) | H5: Балансировка нагрузки между операторами; Совмещение профессий и многостаночность; Автоматизация или механизация работ; Изменение штатного расписания.
B6: Строительство | C6: Белгородская область | D6: высокий уровень запасов незавершенного производства и готовой продукции | E6: м²/чел./мес | F6: ставка | G6: Прорывное улучшение процесса (мероприятия по изменению технологии проведения работ) | H6: Изменение/внедрение оснастки; Замена материалов и сырья; Внедрение альтернативного/высокоскоростного способа обработки; Внедрение нового оборудования.
B7: Сельское хозяйство | C7: Брянская область | D7: высокий уровень брака и затраты на его исправление | E7: шт./чел./ч | F7: ставки
B8: Пищевая промышленность | C8: Владимирская область | D8: перерасход сырья и неучтенные потери сырья | E8: шт./чел./см | F8: ставок
B9: Горнодобывающая промышленность | C9: Волгоградская область | D9: рост и превышение плановой себестоимости продукции | E9: шт./чел./сут
B10: Легкая промышленность | C10: Вологодская область | D10: частые поломки оборудования и высокие простои линий | E10: шт./чел./нед
B11: Лесная, деревообрабатывающая и целлюлозно-бумажная промышленность | C11: Воронежская область | D11: недозагрузка оборудования и производственного персонала | E11: шт./чел./мес
B12: Транспорт и логистика | C12: Донецкая Народная Республика | D12: длительное время переналадки и обслуживания оборудования | E12: тыс шт./чел./ч
B13: Энергетика | C13: Еврейская АО | D13: высокая трудоемкость производственных процессов | E13: тыс шт./чел./см
B14: Торговля | C14: Забайкальский край | D14: простой основного производства в ожидании сырья и материалов | E14: тыс шт./чел./сут
B15: Медицинская промышленность | C15: Запорожская область | D15: неэффективная организация складского хозяйства и логистики | E15: тыс шт./чел./нед
B16: Электронная промышленность | C16: Ивановская область | D16: дефицит квалифицированного персонала, высокая текучесть кадров | E16: тыс шт./чел./мес
B17: Социальная сфера | C17: Иркутская область | D17: длительное время обработки запросов и выполнения заказов | E17: кг/чел./ч
B18: Финансовый сектор | C18: Кабардино-Балкарская Республика | D18: снижение количества бронирований, выручки и среднего чека | E18: кг/чел./см
B19: Туризм | C19: Калининградская область | D19: рост себестоимости предоставляемых услуг при снижении доходов | E19: кг/чел./сут
B20: ЖКХ | C20: Калужская область | D20: несвоевременное выполнение задач и срыв сроков проектов | E20: кг/чел./нед
B21: Обрабатывающая промышленность | C21: Камчатский край | D21: слабое кроссфункциональное взаимодействие между отделами | E21: кг/чел./мес
C22: Карачаево-Черкесская Республика | E22: м³/чел./ч
C23: Кемеровская область — Кузбасс | E23: м³/чел./см
C24: Кировская область | E24: м³/чел./сут
C25: Костромская область | E25: м³/чел./нед
C26: Краснодарский край | E26: м³/чел./мес
C27: Красноярский край | E27: т/чел./ч
C28: Курганская область | E28: т/чел./см
C29: Курская область | E29: т/чел./сут
C30: Ленинградская область | E30: т/чел./нед
C31: Липецкая область | E31: т/чел./мес
C32: Луганская Народная Республика | E32: млн руб./чел./мес
C33: Магаданская область | E33: млн руб./чел./год
C34: Москва | E34: ='Своя ед.изм'!H3 -> 0
C35: Московская область
C36: Мурманская область
C37: Ненецкий АО
C38: Нижегородская область
C39: Новгородская область
C40: Новосибирская область
...

Sheet ОКВЭД2
A1: ОКВЭД-2
A3: Код | B3: Наименование
A4: A | B4: СЕЛЬСКОЕ, ЛЕСНОЕ ХОЗЯЙСТВО, ОХОТА, РЫБОЛОВСТВО И РЫБОВОДСТВО
A5: 01 | B5: Растениеводство и животноводство, охота и предоставление соответствующих услуг в этих областях
A6: 01.1 | B6: Выращивание однолетних культур
A7: 01.11 | B7: Выращивание зерновых (кроме риса), зернобобовых культур и семян масличных культур
A8: 01.11.1 | B8: Выращивание зерновых культур
A9: 01.11.11 | B9: Выращивание пшеницы
A10: 01.11.12 | B10: Выращивание ячменя
A11: 01.11.13 | B11: Выращивание ржи
A12: 01.11.14 | B12: Выращивание кукурузы
A13: 01.11.15 | B13: Выращивание овса
A14: 01.11.16 | B14: Выращивание гречихи
... A2795: 66.19.7 | B2795: Рейтинговая деятельность
